<?xml version="1.0"?>
<robot name="advanced_humanoid" xmlns:xacro="http://www.ros.org/wiki/xacro">

  <!-- Materials -->
  <material name="black">
    <color rgba="0.0 0.0 0.0 1.0"/>
  </material>
  <material name="blue">
    <color rgba="0.0 0.0 0.8 1.0"/>
  </material>
  <material name="green">
    <color rgba="0.0 0.8 0.0 1.0"/>
  </material>
  <material name="grey">
    <color rgba="0.5 0.5 0.5 1.0"/>
  </material>
  <material name="silver">
    <color rgba="0.9 0.9 0.9 1.0"/>
  </material>
  <material name="orange">
    <color rgba="1.0 0.423529411765 0.0392156862745 1.0"/>
  </material>
  <material name="brown">
    <color rgba="0.870588235294 0.811764705882 0.764705882353 1.0"/>
  </material>
  <material name="red">
    <color rgba="0.8 0.0 0.0 1.0"/>
  </material>
  <material name="white">
    <color rgba="1.0 1.0 1.0 1.0"/>
  </material>

  <!-- Base/Torso Link -->
  <link name="base_link">
    <visual>
      <origin xyz="0 0 0.35" rpy="0 0 0"/>
      <geometry>
        <box size="0.25 0.2 0.7"/>
      </geometry>
      <material name="grey"/>
    </visual>
    <collision>
      <origin xyz="0 0 0.35" rpy="0 0 0"/>
      <geometry>
        <box size="0.25 0.2 0.7"/>
      </geometry>
    </collision>
    <inertial>
      <origin xyz="0 0 0.35" rpy="0 0 0"/>
      <mass value="10.0"/>
      <inertia ixx="0.4" ixy="0.0" ixz="0.0" iyy="0.5" iyz="0.0" izz="0.2"/>
    </inertial>
  </link>

  <!-- Head -->
  <link name="head">
    <visual>
      <origin xyz="0 0 0.075" rpy="0 0 0"/>
      <geometry>
        <cylinder radius="0.12" length="0.15"/>
      </geometry>
      <material name="brown"/>
    </visual>
    <collision>
      <origin xyz="0 0 0.075" rpy="0 0 0"/>
      <geometry>
        <cylinder radius="0.12" length="0.15"/>
      </geometry>
    </collision>
    <inertial>
      <origin xyz="0 0 0.075" rpy="0 0 0"/>
      <mass value="2.0"/>
      <inertia ixx="0.01" ixy="0.0" ixz="0.0" iyy="0.01" iyz="0.0" izz="0.01"/>
    </inertial>
  </link>

  <joint name="neck_joint" type="revolute">
    <parent link="base_link"/>
    <child link="head"/>
    <origin xyz="0 0 0.7" rpy="0 0 0"/>
    <axis xyz="0 1 0"/>
    <limit lower="-0.5" upper="0.5" effort="50" velocity="3"/>
    <dynamics damping="1.0" friction="0.1"/>
  </joint>

  <!-- Left Arm -->
  <link name="left_shoulder">
    <visual>
      <geometry>
        <sphere radius="0.05"/>
      </geometry>
      <material name="silver"/>
    </visual>
    <collision>
      <geometry>
        <sphere radius="0.05"/>
      </geometry>
    </collision>
    <inertial>
      <mass value="0.5"/>
      <inertia ixx="0.0001" ixy="0.0" ixz="0.0" iyy="0.0001" iyz="0.0" izz="0.0001"/>
    </inertial>
  </link>

  <joint name="left_shoulder_yaw" type="revolute">
    <parent link="base_link"/>
    <child link="left_shoulder"/>
    <origin xyz="0.15 0.12 0.45" rpy="0 0 0"/>
    <axis xyz="0 0 1"/>
    <limit lower="-1.57" upper="1.57" effort="100" velocity="3"/>
    <dynamics damping="1.0" friction="0.1"/>
  </joint>

  <link name="left_upper_arm">
    <visual>
      <origin xyz="0 0 -0.15" rpy="1.57 0 0"/>
      <geometry>
        <cylinder radius="0.04" length="0.3"/>
      </geometry>
      <material name="blue"/>
    </visual>
    <collision>
      <origin xyz="0 0 -0.15" rpy="1.57 0 0"/>
      <geometry>
        <cylinder radius="0.04" length="0.3"/>
      </geometry>
    </collision>
    <inertial>
      <origin xyz="0 0 -0.15" rpy="1.57 0 0"/>
      <mass value="1.5"/>
      <inertia ixx="0.01" ixy="0.0" ixz="0.0" iyy="0.01" iyz="0.0" izz="0.001"/>
    </inertial>
  </link>

  <joint name="left_shoulder_pitch" type="revolute">
    <parent link="left_shoulder"/>
    <child link="left_upper_arm"/>
    <origin xyz="0 0 0" rpy="0 0 0"/>
    <axis xyz="0 1 0"/>
    <limit lower="-2.0" upper="1.0" effort="100" velocity="3"/>
    <dynamics damping="1.0" friction="0.1"/>
  </joint>

  <link name="left_forearm">
    <visual>
      <origin xyz="0 0 -0.12" rpy="1.57 0 0"/>
      <geometry>
        <cylinder radius="0.03" length="0.24"/>
      </geometry>
      <material name="blue"/>
    </visual>
    <collision>
      <origin xyz="0 0 -0.12" rpy="1.57 0 0"/>
      <geometry>
        <cylinder radius="0.03" length="0.24"/>
      </geometry>
    </collision>
    <inertial>
      <origin xyz="0 0 -0.12" rpy="1.57 0 0"/>
      <mass value="1.0"/>
      <inertia ixx="0.005" ixy="0.0" ixz="0.0" iyy="0.005" iyz="0.0" izz="0.0005"/>
    </inertial>
  </link>

  <joint name="left_elbow_joint" type="revolute">
    <parent link="left_upper_arm"/>
    <child link="left_forearm"/>
    <origin xyz="0 0 -0.3" rpy="0 0 0"/>
    <axis xyz="0 0 1"/>
    <limit lower="-2.5" upper="0.0" effort="80" velocity="3"/>
    <dynamics damping="1.0" friction="0.1"/>
  </joint>

  <link name="left_hand">
    <visual>
      <geometry>
        <box size="0.1 0.08 0.15"/>
      </geometry>
      <material name="brown"/>
    </visual>
    <collision>
      <geometry>
        <box size="0.1 0.08 0.15"/>
      </geometry>
    </collision>
    <inertial>
      <mass value="0.3"/>
      <inertia ixx="0.001" ixy="0.0" ixz="0.0" iyy="0.001" iyz="0.0" izz="0.001"/>
    </inertial>
  </link>

  <joint name="left_wrist_joint" type="revolute">
    <parent link="left_forearm"/>
    <child link="left_hand"/>
    <origin xyz="0 0 -0.24" rpy="0 0 0"/>
    <axis xyz="0 1 0"/>
    <limit lower="-1.0" upper="1.0" effort="50" velocity="3"/>
    <dynamics damping="0.5" friction="0.05"/>
  </joint>

  <!-- Right Arm (symmetric to left) -->
  <link name="right_shoulder">
    <visual>
      <geometry>
        <sphere radius="0.05"/>
      </geometry>
      <material name="silver"/>
    </visual>
    <collision>
      <geometry>
        <sphere radius="0.05"/>
      </geometry>
    </collision>
    <inertial>
      <mass value="0.5"/>
      <inertia ixx="0.0001" ixy="0.0" ixz="0.0" iyy="0.0001" iyz="0.0" izz="0.0001"/>
    </inertial>
  </link>

  <joint name="right_shoulder_yaw" type="revolute">
    <parent link="base_link"/>
    <child link="right_shoulder"/>
    <origin xyz="0.15 -0.12 0.45" rpy="0 0 0"/>
    <axis xyz="0 0 1"/>
    <limit lower="-1.57" upper="1.57" effort="100" velocity="3"/>
    <dynamics damping="1.0" friction="0.1"/>
  </joint>

  <link name="right_upper_arm">
    <visual>
      <origin xyz="0 0 -0.15" rpy="1.57 0 0"/>
      <geometry>
        <cylinder radius="0.04" length="0.3"/>
      </geometry>
      <material name="blue"/>
    </visual>
    <collision>
      <origin xyz="0 0 -0.15" rpy="1.57 0 0"/>
      <geometry>
        <cylinder radius="0.04" length="0.3"/>
      </geometry>
    </collision>
    <inertial>
      <origin xyz="0 0 -0.15" rpy="1.57 0 0"/>
      <mass value="1.5"/>
      <inertia ixx="0.01" ixy="0.0" ixz="0.0" iyy="0.01" iyz="0.0" izz="0.001"/>
    </inertial>
  </link>

  <joint name="right_shoulder_pitch" type="revolute">
    <parent link="right_shoulder"/>
    <child link="right_upper_arm"/>
    <origin xyz="0 0 0" rpy="0 0 0"/>
    <axis xyz="0 1 0"/>
    <limit lower="-2.0" upper="1.0" effort="100" velocity="3"/>
    <dynamics damping="1.0" friction="0.1"/>
  </joint>

  <link name="right_forearm">
    <visual>
      <origin xyz="0 0 -0.12" rpy="1.57 0 0"/>
      <geometry>
        <cylinder radius="0.03" length="0.24"/>
      </geometry>
      <material name="blue"/>
    </visual>
    <collision>
      <origin xyz="0 0 -0.12" rpy="1.57 0 0"/>
      <geometry>
        <cylinder radius="0.03" length="0.24"/>
      </geometry>
    </collision>
    <inertial>
      <origin xyz="0 0 -0.12" rpy="1.57 0 0"/>
      <mass value="1.0"/>
      <inertia ixx="0.005" ixy="0.0" ixz="0.0" iyy="0.005" iyz="0.0" izz="0.0005"/>
    </inertial>
  </link>

  <joint name="right_elbow_joint" type="revolute">
    <parent link="right_upper_arm"/>
    <child link="right_forearm"/>
    <origin xyz="0 0 -0.3" rpy="0 0 0"/>
    <axis xyz="0 0 1"/>
    <limit lower="-2.5" upper="0.0" effort="80" velocity="3"/>
    <dynamics damping="1.0" friction="0.1"/>
  </joint>

  <link name="right_hand">
    <visual>
      <geometry>
        <box size="0.1 0.08 0.15"/>
      </geometry>
      <material name="brown"/>
    </visual>
    <collision>
      <geometry>
        <box size="0.1 0.08 0.15"/>
      </geometry>
    </collision>
    <inertial>
      <mass value="0.3"/>
      <inertia ixx="0.001" ixy="0.0" ixz="0.0" iyy="0.001" iyz="0.0" izz="0.001"/>
    </inertial>
  </link>

  <joint name="right_wrist_joint" type="revolute">
    <parent link="right_forearm"/>
    <child link="right_hand"/>
    <origin xyz="0 0 -0.24" rpy="0 0 0"/>
    <axis xyz="0 1 0"/>
    <limit lower="-1.0" upper="1.0" effort="50" velocity="3"/>
    <dynamics damping="0.5" friction="0.05"/>
  </joint>

  <!-- Left Leg -->
  <link name="left_hip">
    <visual>
      <geometry>
        <sphere radius="0.06"/>
      </geometry>
      <material name="silver"/>
    </visual>
    <collision>
      <geometry>
        <sphere radius="0.06"/>
      </geometry>
    </collision>
    <inertial>
      <mass value="0.8"/>
      <inertia ixx="0.0002" ixy="0.0" ixz="0.0" iyy="0.0002" iyz="0.0" izz="0.0002"/>
    </inertial>
  </link>

  <joint name="left_hip_yaw" type="revolute">
    <parent link="base_link"/>
    <child link="left_hip"/>
    <origin xyz="-0.15 0.08 0" rpy="0 0 0"/>
    <axis xyz="0 0 1"/>
    <limit lower="-0.5" upper="0.5" effort="150" velocity="3"/>
    <dynamics damping="2.0" friction="0.2"/>
  </joint>

  <link name="left_thigh">
    <visual>
      <origin xyz="0 0 -0.2" rpy="1.57 0 0"/>
      <geometry>
        <cylinder radius="0.06" length="0.4"/>
      </geometry>
      <material name="green"/>
    </visual>
    <collision>
      <origin xyz="0 0 -0.2" rpy="1.57 0 0"/>
      <geometry>
        <cylinder radius="0.06" length="0.4"/>
      </geometry>
    </collision>
    <inertial>
      <origin xyz="0 0 -0.2" rpy="1.57 0 0"/>
      <mass value="3.0"/>
      <inertia ixx="0.04" ixy="0.0" ixz="0.0" iyy="0.04" iyz="0.0" izz="0.003"/>
    </inertial>
  </link>

  <joint name="left_hip_pitch" type="revolute">
    <parent link="left_hip"/>
    <child link="left_thigh"/>
    <origin xyz="0 0 0" rpy="0 0 0"/>
    <axis xyz="0 1 0"/>
    <limit lower="-2.0" upper="0.5" effort="150" velocity="3"/>
    <dynamics damping="2.0" friction="0.2"/>
  </joint>

  <link name="left_shin">
    <visual>
      <origin xyz="0 0 -0.2" rpy="1.57 0 0"/>
      <geometry>
        <cylinder radius="0.05" length="0.4"/>
      </geometry>
      <material name="green"/>
    </visual>
    <collision>
      <origin xyz="0 0 -0.2" rpy="1.57 0 0"/>
      <geometry>
        <cylinder radius="0.05" length="0.4"/>
      </geometry>
    </collision>
    <inertial>
      <origin xyz="0 0 -0.2" rpy="1.57 0 0"/>
      <mass value="2.5"/>
      <inertia ixx="0.03" ixy="0.0" ixz="0.0" iyy="0.03" iyz="0.0" izz="0.002"/>
    </inertial>
  </link>

  <joint name="left_knee_joint" type="revolute">
    <parent link="left_thigh"/>
    <child link="left_shin"/>
    <origin xyz="0 0 -0.4" rpy="0 0 0"/>
    <axis xyz="0 1 0"/>
    <limit lower="0" upper="2.3" effort="150" velocity="3"/>
    <dynamics damping="2.0" friction="0.2"/>
  </joint>

  <link name="left_foot">
    <visual>
      <geometry>
        <box size="0.25 0.12 0.08"/>
      </geometry>
      <material name="white"/>
    </visual>
    <collision>
      <geometry>
        <box size="0.25 0.12 0.08"/>
      </geometry>
    </collision>
    <inertial>
      <mass value="1.0"/>
      <inertia ixx="0.002" ixy="0.0" ixz="0.0" iyy="0.005" iyz="0.0" izz="0.005"/>
    </inertial>
  </link>

  <joint name="left_ankle_joint" type="revolute">
    <parent link="left_shin"/>
    <child link="left_foot"/>
    <origin xyz="0 0 -0.4" rpy="0 0 0"/>
    <axis xyz="0 0 1"/>
    <limit lower="-0.5" upper="0.5" effort="100" velocity="3"/>
    <dynamics damping="1.0" friction="0.1"/>
  </joint>

  <!-- Right Leg (symmetric to left) -->
  <link name="right_hip">
    <visual>
      <geometry>
        <sphere radius="0.06"/>
      </geometry>
      <material name="silver"/>
    </visual>
    <collision>
      <geometry>
        <sphere radius="0.06"/>
      </geometry>
    </collision>
    <inertial>
      <mass value="0.8"/>
      <inertia ixx="0.0002" ixy="0.0" ixz="0.0" iyy="0.0002" iyz="0.0" izz="0.0002"/>
    </inertial>
  </link>

  <joint name="right_hip_yaw" type="revolute">
    <parent link="base_link"/>
    <child link="right_hip"/>
    <origin xyz="-0.15 -0.08 0" rpy="0 0 0"/>
    <axis xyz="0 0 1"/>
    <limit lower="-0.5" upper="0.5" effort="150" velocity="3"/>
    <dynamics damping="2.0" friction="0.2"/>
  </joint>

  <link name="right_thigh">
    <visual>
      <origin xyz="0 0 -0.2" rpy="1.57 0 0"/>
      <geometry>
        <cylinder radius="0.06" length="0.4"/>
      </geometry>
      <material name="green"/>
    </visual>
    <collision>
      <origin xyz="0 0 -0.2" rpy="1.57 0 0"/>
      <geometry>
        <cylinder radius="0.06" length="0.4"/>
      </geometry>
    </collision>
    <inertial>
      <origin xyz="0 0 -0.2" rpy="1.57 0 0"/>
      <mass value="3.0"/>
      <inertia ixx="0.04" ixy="0.0" ixz="0.0" iyy="0.04" iyz="0.0" izz="0.003"/>
    </inertial>
  </link>

  <joint name="right_hip_pitch" type="revolute">
    <parent link="right_hip"/>
    <child link="right_thigh"/>
    <origin xyz="0 0 0" rpy="0 0 0"/>
    <axis xyz="0 1 0"/>
    <limit lower="-2.0" upper="0.5" effort="150" velocity="3"/>
    <dynamics damping="2.0" friction="0.2"/>
  </joint>

  <link name="right_shin">
    <visual>
      <origin xyz="0 0 -0.2" rpy="1.57 0 0"/>
      <geometry>
        <cylinder radius="0.05" length="0.4"/>
      </geometry>
      <material name="green"/>
    </visual>
    <collision>
      <origin xyz="0 0 -0.2" rpy="1.57 0 0"/>
      <geometry>
        <cylinder radius="0.05" length="0.4"/>
      </geometry>
    </collision>
    <inertial>
      <origin xyz="0 0 -0.2" rpy="1.57 0 0"/>
      <mass value="2.5"/>
      <inertia ixx="0.03" ixy="0.0" ixz="0.0" iyy="0.03" iyz="0.0" izz="0.002"/>
    </inertial>
  </link>

  <joint name="right_knee_joint" type="revolute">
    <parent link="right_thigh"/>
    <child link="right_shin"/>
    <origin xyz="0 0 -0.4" rpy="0 0 0"/>
    <axis xyz="0 1 0"/>
    <limit lower="0" upper="2.3" effort="150" velocity="3"/>
    <dynamics damping="2.0" friction="0.2"/>
  </joint>

  <link name="right_foot">
    <visual>
      <geometry>
        <box size="0.25 0.12 0.08"/>
      </geometry>
      <material name="white"/>
    </visual>
    <collision>
      <geometry>
        <box size="0.25 0.12 0.08"/>
      </geometry>
    </collision>
    <inertial>
      <mass value="1.0"/>
      <inertia ixx="0.002" ixy="0.0" ixz="0.0" iyy="0.005" iyz="0.0" izz="0.005"/>
    </inertial>
  </link>

  <joint name="right_ankle_joint" type="revolute">
    <parent link="right_shin"/>
    <child link="right_foot"/>
    <origin xyz="0 0 -0.4" rpy="0 0 0"/>
    <axis xyz="0 0 1"/>
    <limit lower="-0.5" upper="0.5" effort="100" velocity="3"/>
    <dynamics damping="1.0" friction="0.1"/>
  </joint>

  <!-- Gazebo-specific elements -->
  <gazebo reference="base_link">
    <material>Gazebo/Grey</material>
  </gazebo>

  <gazebo reference="head">
    <material>Gazebo/Purple</material>
  </gazebo>

  <gazebo>
    <plugin name="gazebo_ros_control" filename="libgazebo_ros_control.so">
      <robotNamespace>/advanced_humanoid</robotNamespace>
    </plugin>
  </gazebo>

</robot>