<?xml version="1.0"?>
<robot name="simple_humanoid">
  <!-- Base/Torso Link -->
  <link name="base_link">
    <visual>
      <origin xyz="0 0 0.3" rpy="0 0 0"/>
      <geometry>
        <box size="0.3 0.2 0.6"/>
      </geometry>
      <material name="light_gray">
        <color rgba="0.7 0.7 0.7 1.0"/>
      </material>
    </visual>
    <collision>
      <origin xyz="0 0 0.3" rpy="0 0 0"/>
      <geometry>
        <box size="0.3 0.2 0.6"/>
      </geometry>
    </collision>
    <inertial>
      <origin xyz="0 0 0.3" rpy="0 0 0"/>
      <mass value="5.0"/>
      <inertia ixx="0.2" ixy="0" ixz="0" iyy="0.3" iyz="0" izz="0.1"/>
    </inertial>
  </link>

  <!-- Head -->
  <link name="head">
    <visual>
      <origin xyz="0 0 0.05" rpy="0 0 0"/>
      <geometry>
        <sphere radius="0.1"/>
      </geometry>
      <material name="skin">
        <color rgba="0.9 0.8 0.6 1.0"/>
      </material>
    </visual>
    <collision>
      <origin xyz="0 0 0.05" rpy="0 0 0"/>
      <geometry>
        <sphere radius="0.1"/>
      </geometry>
    </collision>
    <inertial>
      <origin xyz="0 0 0.05" rpy="0 0 0"/>
      <mass value="1.0"/>
      <inertia ixx="0.004" ixy="0" ixz="0" iyy="0.004" iyz="0" izz="0.004"/>
    </inertial>
  </link>

  <joint name="neck_joint" type="revolute">
    <parent link="base_link"/>
    <child link="head"/>
    <origin xyz="0 0 0.6" rpy="0 0 0"/>
    <axis xyz="0 1 0"/>
    <limit lower="-0.5" upper="0.5" effort="10" velocity="2"/>
  </joint>

  <!-- Left Arm -->
  <!-- Left Shoulder -->
  <link name="left_shoulder">
    <visual>
      <origin xyz="0 0 0" rpy="0 0 0"/>
      <geometry>
        <cylinder radius="0.05" length="0.1"/>
      </geometry>
      <material name="joint_color">
        <color rgba="0.5 0.5 0.5 1.0"/>
      </material>
    </visual>
    <collision>
      <geometry>
        <cylinder radius="0.05" length="0.1"/>
      </geometry>
    </collision>
    <inertial>
      <mass value="0.5"/>
      <inertia ixx="0.001" ixy="0" ixz="0" iyy="0.001" iyz="0" izz="0.0005"/>
    </inertial>
  </link>

  <joint name="left_shoulder_joint" type="revolute">
    <parent link="base_link"/>
    <child link="left_shoulder"/>
    <origin xyz="0.15 0.1 0.4" rpy="0 0 0"/>
    <axis xyz="0 1 0"/>
    <limit lower="-1.57" upper="1.57" effort="20" velocity="2"/>
  </joint>

  <!-- Left Upper Arm -->
  <link name="left_upper_arm">
    <visual>
      <origin xyz="0 0 -0.15" rpy="1.57 0 0"/>
      <geometry>
        <cylinder radius="0.04" length="0.3"/>
      </geometry>
      <material name="arm_color">
        <color rgba="0.6 0.6 0.8 1.0"/>
      </material>
    </visual>
    <collision>
      <origin xyz="0 0 -0.15" rpy="1.57 0 0"/>
      <geometry>
        <cylinder radius="0.04" length="0.3"/>
      </geometry>
    </collision>
    <inertial>
      <origin xyz="0 0 -0.15" rpy="1.57 0 0"/>
      <mass value="1.0"/>
      <inertia ixx="0.01" ixy="0" ixz="0" iyy="0.01" iyz="0" izz="0.001"/>
    </inertial>
  </link>

  <joint name="left_elbow_joint" type="revolute">
    <parent link="left_shoulder"/>
    <child link="left_upper_arm"/>
    <origin xyz="0 0 0" rpy="0 0 0"/>
    <axis xyz="0 0 1"/>
    <limit lower="-2.36" upper="0" effort="15" velocity="2"/>
  </joint>

  <!-- Left Forearm -->
  <link name="left_forearm">
    <visual>
      <origin xyz="0 0 -0.12" rpy="1.57 0 0"/>
      <geometry>
        <cylinder radius="0.03" length="0.24"/>
      </geometry>
      <material name="arm_color">
        <color rgba="0.6 0.6 0.8 1.0"/>
      </material>
    </visual>
    <collision>
      <origin xyz="0 0 -0.12" rpy="1.57 0 0"/>
      <geometry>
        <cylinder radius="0.03" length="0.24"/>
      </geometry>
    </collision>
    <inertial>
      <origin xyz="0 0 -0.12" rpy="1.57 0 0"/>
      <mass value="0.5"/>
      <inertia ixx="0.005" ixy="0" ixz="0" iyy="0.005" iyz="0" izz="0.0005"/>
    </inertial>
  </link>

  <joint name="left_forearm_joint" type="revolute">
    <parent link="left_upper_arm"/>
    <child link="left_forearm"/>
    <origin xyz="0 0 -0.3" rpy="0 0 0"/>
    <axis xyz="0 0 1"/>
    <limit lower="-1.57" upper="1.57" effort="10" velocity="2"/>
  </joint>

  <!-- Right Arm (symmetric to left arm) -->
  <link name="right_shoulder">
    <visual>
      <origin xyz="0 0 0" rpy="0 0 0"/>
      <geometry>
        <cylinder radius="0.05" length="0.1"/>
      </geometry>
      <material name="joint_color">
        <color rgba="0.5 0.5 0.5 1.0"/>
      </material>
    </visual>
    <collision>
      <geometry>
        <cylinder radius="0.05" length="0.1"/>
      </geometry>
    </collision>
    <inertial>
      <mass value="0.5"/>
      <inertia ixx="0.001" ixy="0" ixz="0" iyy="0.001" iyz="0" izz="0.0005"/>
    </inertial>
  </link>

  <joint name="right_shoulder_joint" type="revolute">
    <parent link="base_link"/>
    <child link="right_shoulder"/>
    <origin xyz="0.15 -0.1 0.4" rpy="0 0 0"/>
    <axis xyz="0 1 0"/>
    <limit lower="-1.57" upper="1.57" effort="20" velocity="2"/>
  </joint>

  <link name="right_upper_arm">
    <visual>
      <origin xyz="0 0 -0.15" rpy="1.57 0 0"/>
      <geometry>
        <cylinder radius="0.04" length="0.3"/>
      </geometry>
      <material name="arm_color">
        <color rgba="0.6 0.6 0.8 1.0"/>
      </material>
    </visual>
    <collision>
      <origin xyz="0 0 -0.15" rpy="1.57 0 0"/>
      <geometry>
        <cylinder radius="0.04" length="0.3"/>
      </geometry>
    </collision>
    <inertial>
      <origin xyz="0 0 -0.15" rpy="1.57 0 0"/>
      <mass value="1.0"/>
      <inertia ixx="0.01" ixy="0" ixz="0" iyy="0.01" iyz="0" izz="0.001"/>
    </inertial>
  </link>

  <joint name="right_elbow_joint" type="revolute">
    <parent link="right_shoulder"/>
    <child link="right_upper_arm"/>
    <origin xyz="0 0 0" rpy="0 0 0"/>
    <axis xyz="0 0 1"/>
    <limit lower="-2.36" upper="0" effort="15" velocity="2"/>
  </joint>

  <link name="right_forearm">
    <visual>
      <origin xyz="0 0 -0.12" rpy="1.57 0 0"/>
      <geometry>
        <cylinder radius="0.03" length="0.24"/>
      </geometry>
      <material name="arm_color">
        <color rgba="0.6 0.6 0.8 1.0"/>
      </material>
    </visual>
    <collision>
      <origin xyz="0 0 -0.12" rpy="1.57 0 0"/>
      <geometry>
        <cylinder radius="0.03" length="0.24"/>
      </geometry>
    </collision>
    <inertial>
      <origin xyz="0 0 -0.12" rpy="1.57 0 0"/>
      <mass value="0.5"/>
      <inertia ixx="0.005" ixy="0" ixz="0" iyy="0.005" iyz="0" izz="0.0005"/>
    </inertial>
  </link>

  <joint name="right_forearm_joint" type="revolute">
    <parent link="right_upper_arm"/>
    <child link="right_forearm"/>
    <origin xyz="0 0 -0.3" rpy="0 0 0"/>
    <axis xyz="0 0 1"/>
    <limit lower="-1.57" upper="1.57" effort="10" velocity="2"/>
  </joint>

  <!-- Left Leg -->
  <link name="left_hip">
    <visual>
      <geometry>
        <cylinder radius="0.06" length="0.1"/>
      </geometry>
      <material name="joint_color">
        <color rgba="0.5 0.5 0.5 1.0"/>
      </material>
    </visual>
    <collision>
      <geometry>
        <cylinder radius="0.06" length="0.1"/>
      </geometry>
    </collision>
    <inertial>
      <mass value="0.5"/>
      <inertia ixx="0.001" ixy="0" ixz="0" iyy="0.001" iyz="0" izz="0.0005"/>
    </inertial>
  </link>

  <joint name="left_hip_joint" type="revolute">
    <parent link="base_link"/>
    <child link="left_hip"/>
    <origin xyz="-0.15 0.08 0" rpy="0 0 0"/>
    <axis xyz="0 0 1"/>
    <limit lower="-0.5" upper="0.5" effort="30" velocity="2"/>
  </joint>

  <link name="left_thigh">
    <visual>
      <origin xyz="0 0 -0.2" rpy="1.57 0 0"/>
      <geometry>
        <cylinder radius="0.05" length="0.4"/>
      </geometry>
      <material name="leg_color">
        <color rgba="0.4 0.4 0.6 1.0"/>
      </material>
    </visual>
    <collision>
      <origin xyz="0 0 -0.2" rpy="1.57 0 0"/>
      <geometry>
        <cylinder radius="0.05" length="0.4"/>
      </geometry>
    </collision>
    <inertial>
      <origin xyz="0 0 -0.2" rpy="1.57 0 0"/>
      <mass value="2.0"/>
      <inertia ixx="0.03" ixy="0" ixz="0" iyy="0.03" iyz="0" izz="0.002"/>
    </inertial>
  </link>

  <joint name="left_knee_joint" type="revolute">
    <parent link="left_hip"/>
    <child link="left_thigh"/>
    <origin xyz="0 0 0" rpy="0 0 0"/>
    <axis xyz="0 0 1"/>
    <limit lower="0" upper="2.36" effort="30" velocity="2"/>
  </joint>

  <link name="left_shin">
    <visual>
      <origin xyz="0 0 -0.2" rpy="1.57 0 0"/>
      <geometry>
        <cylinder radius="0.04" length="0.4"/>
      </geometry>
      <material name="leg_color">
        <color rgba="0.4 0.4 0.6 1.0"/>
      </material>
    </visual>
    <collision>
      <origin xyz="0 0 -0.2" rpy="1.57 0 0"/>
      <geometry>
        <cylinder radius="0.04" length="0.4"/>
      </geometry>
    </collision>
    <inertial>
      <origin xyz="0 0 -0.2" rpy="1.57 0 0"/>
      <mass value="1.5"/>
      <inertia ixx="0.02" ixy="0" ixz="0" iyy="0.02" iyz="0" izz="0.0015"/>
    </inertial>
  </link>

  <joint name="left_ankle_joint" type="revolute">
    <parent link="left_thigh"/>
    <child link="left_shin"/>
    <origin xyz="0 0 -0.4" rpy="0 0 0"/>
    <axis xyz="0 0 1"/>
    <limit lower="-0.5" upper="0.5" effort="20" velocity="2"/>
  </joint>

  <!-- Right Leg (symmetric to left leg) -->
  <link name="right_hip">
    <visual>
      <geometry>
        <cylinder radius="0.06" length="0.1"/>
      </geometry>
      <material name="joint_color">
        <color rgba="0.5 0.5 0.5 1.0"/>
      </material>
    </visual>
    <collision>
      <geometry>
        <cylinder radius="0.06" length="0.1"/>
      </geometry>
    </collision>
    <inertial>
      <mass value="0.5"/>
      <inertia ixx="0.001" ixy="0" ixz="0" iyy="0.001" iyz="0" izz="0.0005"/>
    </inertial>
  </link>

  <joint name="right_hip_joint" type="revolute">
    <parent link="base_link"/>
    <child link="right_hip"/>
    <origin xyz="-0.15 -0.08 0" rpy="0 0 0"/>
    <axis xyz="0 0 1"/>
    <limit lower="-0.5" upper="0.5" effort="30" velocity="2"/>
  </joint>

  <link name="right_thigh">
    <visual>
      <origin xyz="0 0 -0.2" rpy="1.57 0 0"/>
      <geometry>
        <cylinder radius="0.05" length="0.4"/>
      </geometry>
      <material name="leg_color">
        <color rgba="0.4 0.4 0.6 1.0"/>
      </material>
    </visual>
    <collision>
      <origin xyz="0 0 -0.2" rpy="1.57 0 0"/>
      <geometry>
        <cylinder radius="0.05" length="0.4"/>
      </geometry>
    </collision>
    <inertial>
      <origin xyz="0 0 -0.2" rpy="1.57 0 0"/>
      <mass value="2.0"/>
      <inertia ixx="0.03" ixy="0" ixz="0" iyy="0.03" iyz="0" izz="0.002"/>
    </inertial>
  </link>

  <joint name="right_knee_joint" type="revolute">
    <parent link="right_hip"/>
    <child link="right_thigh"/>
    <origin xyz="0 0 0" rpy="0 0 0"/>
    <axis xyz="0 0 1"/>
    <limit lower="0" upper="2.36" effort="30" velocity="2"/>
  </joint>

  <link name="right_shin">
    <visual>
      <origin xyz="0 0 -0.2" rpy="1.57 0 0"/>
      <geometry>
        <cylinder radius="0.04" length="0.4"/>
      </geometry>
      <material name="leg_color">
        <color rgba="0.4 0.4 0.6 1.0"/>
      </material>
    </visual>
    <collision>
      <origin xyz="0 0 -0.2" rpy="1.57 0 0"/>
      <geometry>
        <cylinder radius="0.04" length="0.4"/>
      </geometry>
    </collision>
    <inertial>
      <origin xyz="0 0 -0.2" rpy="1.57 0 0"/>
      <mass value="1.5"/>
      <inertia ixx="0.02" ixy="0" ixz="0" iyy="0.02" iyz="0" izz="0.0015"/>
    </inertial>
  </link>

  <joint name="right_ankle_joint" type="revolute">
    <parent link="right_thigh"/>
    <child link="right_shin"/>
    <origin xyz="0 0 -0.4" rpy="0 0 0"/>
    <axis xyz="0 0 1"/>
    <limit lower="-0.5" upper="0.5" effort="20" velocity="2"/>
  </joint>
</robot>